<mujoco model="panda">
    <compiler angle="radian" autolimits="true"/>

    <default>
      <default class="panda">
        <joint armature="0.1" damping="1" axis="0 0 1" range="-2.8973 2.8973"/>
        <default class="panda/visual">
          <geom type="mesh" contype="0" conaffinity="0" group="2"/>
        </default>
        <default class="panda/collision">
          <geom type="mesh" group="3"/>
        </default>
        <site size="0.001" rgba="0.5 0.5 0.5 0.3" group="4"/>
      </default>
      <default class="changingtek">
        <default class="changingtek/visual">
          <geom group="2" type="mesh" contype="0" conaffinity="0"/>
        </default>
        <default class="changingtek/collision">
          <geom group="3" type="mesh" condim="6" contype="0" conaffinity="1" priority="1"
           solimp="0.95 0.99 0.001" solref="0.004 1" friction="5 5 5"/>
        </default>
        <joint axis="1 0 0"/>
      </default>
    </default>

    <asset>
      <material name="white" rgba="1 1 1 1"/>
      <material name="off_white" rgba="0.901961 0.921569 0.929412 1"/>
      <material name="dark_grey" rgba="0.25 0.25 0.25 1"/>
      <material name="green" rgba="0 1 0 1"/>
      <material name="light_blue" rgba="0.039216 0.541176 0.780392 1"/>
      <material name="metal" rgba="0.58 0.58 0.58 1"/>
      <material name="silicone" rgba="0.1882 0.1882 0.1882 1"/>
      <material name="gray" rgba="0.4627 0.4627 0.4627 1"/>
      <material name="black" rgba="0.149 0.149 0.149 1"/>
      <material name="black_metal" specular="0.5" shininess="0.49" rgba="0.010000 0.010000 0.010000 1.000000"/>
      <material name="black_rubber" specular="0.5" shininess="0.09" rgba="0.050000 0.050000 0.050000 1.000000"/>
      <material name="silver" specular="0.5" shininess="0.49" rgba="0.800000 0.800000 0.800000 1.000000"/>

      <mesh name="link0_c" file="franka_emika_panda/meshes/link0.stl"/>
      <mesh name="link1_c" file="franka_emika_panda/meshes/link1.stl"/>
      <mesh name="link2_c" file="franka_emika_panda/meshes/link2.stl"/>
      <mesh name="link3_c" file="franka_emika_panda/meshes/link3.stl"/>
      <mesh name="link4_c" file="franka_emika_panda/meshes/link4.stl"/>
      <mesh name="link5_c0" file="franka_emika_panda/meshes/link5_collision_0.obj"/>
      <mesh name="link5_c1" file="franka_emika_panda/meshes/link5_collision_1.obj"/>
      <mesh name="link5_c2" file="franka_emika_panda/meshes/link5_collision_2.obj"/>
      <mesh name="link6_c" file="franka_emika_panda/meshes/link6.stl"/>
      <mesh name="link7_c" file="franka_emika_panda/meshes/link7.stl"/>
      <mesh file="franka_emika_panda/meshes/link0_0.obj"/>
      <mesh file="franka_emika_panda/meshes/link0_1.obj"/>
      <mesh file="franka_emika_panda/meshes/link0_2.obj"/>
      <mesh file="franka_emika_panda/meshes/link0_3.obj"/>
      <mesh file="franka_emika_panda/meshes/link0_4.obj"/>
      <mesh file="franka_emika_panda/meshes/link0_5.obj"/>
      <mesh file="franka_emika_panda/meshes/link0_7.obj"/>
      <mesh file="franka_emika_panda/meshes/link0_8.obj"/>
      <mesh file="franka_emika_panda/meshes/link0_9.obj"/>
      <mesh file="franka_emika_panda/meshes/link0_10.obj"/>
      <mesh file="franka_emika_panda/meshes/link0_11.obj"/>
      <mesh file="franka_emika_panda/meshes/link1.obj"/>
      <mesh file="franka_emika_panda/meshes/link2.obj"/>
      <mesh file="franka_emika_panda/meshes/link3_0.obj"/>
      <mesh file="franka_emika_panda/meshes/link3_1.obj"/>
      <mesh file="franka_emika_panda/meshes/link3_2.obj"/>
      <mesh file="franka_emika_panda/meshes/link3_3.obj"/>
      <mesh file="franka_emika_panda/meshes/link4_0.obj"/>
      <mesh file="franka_emika_panda/meshes/link4_1.obj"/>
      <mesh file="franka_emika_panda/meshes/link4_2.obj"/>
      <mesh file="franka_emika_panda/meshes/link4_3.obj"/>
      <mesh file="franka_emika_panda/meshes/link5_0.obj"/>
      <mesh file="franka_emika_panda/meshes/link5_1.obj"/>
      <mesh file="franka_emika_panda/meshes/link5_2.obj"/>
      <mesh file="franka_emika_panda/meshes/link6_0.obj"/>
      <mesh file="franka_emika_panda/meshes/link6_1.obj"/>
      <mesh file="franka_emika_panda/meshes/link6_2.obj"/>
      <mesh file="franka_emika_panda/meshes/link6_3.obj"/>
      <mesh file="franka_emika_panda/meshes/link6_4.obj"/>
      <mesh file="franka_emika_panda/meshes/link6_5.obj"/>
      <mesh file="franka_emika_panda/meshes/link6_6.obj"/>
      <mesh file="franka_emika_panda/meshes/link6_7.obj"/>
      <mesh file="franka_emika_panda/meshes/link6_8.obj"/>
      <mesh file="franka_emika_panda/meshes/link6_9.obj"/>
      <mesh file="franka_emika_panda/meshes/link6_10.obj"/>
      <mesh file="franka_emika_panda/meshes/link6_11.obj"/>
      <mesh file="franka_emika_panda/meshes/link6_12.obj"/>
      <mesh file="franka_emika_panda/meshes/link6_13.obj"/>
      <mesh file="franka_emika_panda/meshes/link6_14.obj"/>
      <mesh file="franka_emika_panda/meshes/link6_15.obj"/>
      <mesh file="franka_emika_panda/meshes/link6_16.obj"/>
      <mesh file="franka_emika_panda/meshes/link7_0.obj"/>
      <mesh file="franka_emika_panda/meshes/link7_1.obj"/>
      <mesh file="franka_emika_panda/meshes/link7_2.obj"/>
      <mesh file="franka_emika_panda/meshes/link7_3.obj"/>
      <mesh file="franka_emika_panda/meshes/link7_4.obj"/>
      <mesh file="franka_emika_panda/meshes/link7_5.obj"/>
      <mesh file="franka_emika_panda/meshes/link7_6.obj"/>
      <mesh file="franka_emika_panda/meshes/link7_7.obj"/>
      <!-- ChangingTek AG2F90-C gripper meshes -->
      <mesh name="gripper_base_0" file="changingtek/AG2F90-C/gripper_base/gripper_base_0.obj"/>
      <mesh name="gripper_base_1" file="changingtek/AG2F90-C/gripper_base/gripper_base_1.obj"/>
      <mesh name="gripper_base_2" file="changingtek/AG2F90-C/gripper_base/gripper_base_2.obj"/>
      <mesh name="gripper_base_collision_0" file="changingtek/AG2F90-C/gripper_base/gripper_base_collision_0.obj"/>
      <mesh name="gripper_base_collision_1" file="changingtek/AG2F90-C/gripper_base/gripper_base_collision_1.obj"/>
      <mesh name="gripper_base_collision_2" file="changingtek/AG2F90-C/gripper_base/gripper_base_collision_2.obj"/>
      <mesh name="link_1" file="changingtek/AG2F90-C/link_1/link_1.obj"/>
      <mesh name="link_1_collision_0" file="changingtek/AG2F90-C/link_1/link_1_collision_0.obj"/>
      <mesh name="link_1_collision_1" file="changingtek/AG2F90-C/link_1/link_1_collision_1.obj"/>
      <mesh name="link_1_collision_2" file="changingtek/AG2F90-C/link_1/link_1_collision_2.obj"/>
      <mesh name="link_2_0" file="changingtek/AG2F90-C/link_2/link_2_0.obj"/>
      <mesh name="link_2_1" file="changingtek/AG2F90-C/link_2/link_2_1.obj"/>
      <mesh name="link_2_collision_0" file="changingtek/AG2F90-C/link_2/link_2_collision_0.obj"/>
      <mesh name="link_2_collision_1" file="changingtek/AG2F90-C/link_2/link_2_collision_1.obj"/>
      <mesh name="link_2_collision_2" file="changingtek/AG2F90-C/link_2/link_2_collision_2.obj"/>
      <mesh name="in_link" file="changingtek/AG2F90-C/in_link/in_link.obj"/>
      <mesh name="in_link_collision_0" file="changingtek/AG2F90-C/in_link/in_link_collision_0.obj"/>
      <mesh name="in_link_collision_1" file="changingtek/AG2F90-C/in_link/in_link_collision_1.obj"/>
      <mesh name="in_link_collision_2" file="changingtek/AG2F90-C/in_link/in_link_collision_2.obj"/>
      <mesh name="up_link_0" file="changingtek/AG2F90-C/up_link/up_link_0.obj"/>
      <mesh name="up_link_1" file="changingtek/AG2F90-C/up_link/up_link_1.obj"/>
      <mesh name="up_link_collision_0" file="changingtek/AG2F90-C/up_link/up_link_collision_0.obj"/>
      <mesh name="up_link_collision_1" file="changingtek/AG2F90-C/up_link/up_link_collision_1.obj"/>
      <mesh name="up_link_collision_2" file="changingtek/AG2F90-C/up_link/up_link_collision_2.obj"/>
      <mesh name="pad_link" file="changingtek/AG2F90-C/pad_link/pad_link.obj"/>
      <mesh name="pad_link_collision_0" file="changingtek/AG2F90-C/pad_link/pad_link_collision_0.obj"/>
      <mesh name="pad_link_collision_1" file="changingtek/AG2F90-C/pad_link/pad_link_collision_1.obj"/>
      <mesh name="pad_link_collision_2" file="changingtek/AG2F90-C/pad_link/pad_link_collision_2.obj"/>
    </asset>

    <worldbody>
      <body name="link0" childclass="panda">
        <inertial mass="0.629769" pos="-0.041018 -0.00014 0.049974"
          fullinertia="0.00315 0.00388 0.004285 8.2904e-7 0.00015 8.2299e-6"/>
        <geom mesh="link0_0" material="off_white" class="panda/visual"/>
        <geom mesh="link0_1" material="dark_grey" class="panda/visual"/>
        <geom mesh="link0_2" material="off_white" class="panda/visual"/>
        <geom mesh="link0_3" material="dark_grey" class="panda/visual"/>
        <geom mesh="link0_4" material="off_white" class="panda/visual"/>
        <geom mesh="link0_5" material="dark_grey" class="panda/visual"/>
        <geom mesh="link0_7" material="white" class="panda/visual"/>
        <geom mesh="link0_8" material="white" class="panda/visual"/>
        <geom mesh="link0_9" material="dark_grey" class="panda/visual"/>
        <geom mesh="link0_10" material="off_white" class="panda/visual"/>
        <geom mesh="link0_11" material="white" class="panda/visual"/>
        <geom mesh="link0_c" class="panda/collision"/>
        <body name="link1" pos="0 0 0.333">
          <inertial mass="4.970684" pos="0.003875 0.002081 -0.04762"
            fullinertia="0.70337 0.70661 0.0091170 -0.00013900 0.0067720 0.019169"/>
          <joint name="joint1"/>
          <site name="joint1"/>
          <geom material="white" mesh="link1" class="panda/visual"/>
          <geom mesh="link1_c" class="panda/collision"/>
          <body name="link2" quat="1 -1 0 0">
            <inertial mass="0.646926" pos="-0.003141 -0.02872 0.003495"
              fullinertia="0.0079620 2.8110e-2 2.5995e-2 -3.925e-3 1.0254e-2 7.04e-4"/>
            <joint name="joint2" range="-1.7628 1.7628"/>
            <site name="joint2"/>
            <geom material="white" mesh="link2" class="panda/visual"/>
            <geom mesh="link2_c" class="panda/collision"/>
            <body name="link3" pos="0 -0.316 0" quat="1 1 0 0">
              <inertial mass="3.228604" pos="2.7518e-2 3.9252e-2 -6.6502e-2"
                fullinertia="3.7242e-2 3.6155e-2 1.083e-2 -4.761e-3 -1.1396e-2 -1.2805e-2"/>
              <joint name="joint3"/>
              <site name="joint3"/>
              <geom mesh="link3_0" material="white" class="panda/visual"/>
              <geom mesh="link3_1" material="white" class="panda/visual"/>
              <geom mesh="link3_2" material="white" class="panda/visual"/>
              <geom mesh="link3_3" material="dark_grey" class="panda/visual"/>
              <geom mesh="link3_c" class="panda/collision"/>
              <body name="link4" pos="0.0825 0 0" quat="1 1 0 0">
                <inertial mass="3.587895" pos="-5.317e-2 1.04419e-1 2.7454e-2"
                  fullinertia="2.5853e-2 1.9552e-2 2.8323e-2 7.796e-3 -1.332e-3 8.641e-3"/>
                <joint name="joint4" range="-3.0718 -0.0698"/>
                <site name="joint4"/>
                <geom mesh="link4_0" material="white" class="panda/visual"/>
                <geom mesh="link4_1" material="white" class="panda/visual"/>
                <geom mesh="link4_2" material="dark_grey" class="panda/visual"/>
                <geom mesh="link4_3" material="white" class="panda/visual"/>
                <geom mesh="link4_c" class="panda/collision"/>
                <body name="link5" pos="-0.0825 0.384 0" quat="1 -1 0 0">
                  <inertial mass="1.225946" pos="-1.1953e-2 4.1065e-2 -3.8437e-2"
                    fullinertia="3.5549e-2 2.9474e-2 8.627e-3 -2.117e-3 -4.037e-3 2.29e-4"/>
                  <joint name="joint5"/>
                  <site name="joint5"/>
                  <geom mesh="link5_0" material="dark_grey" class="panda/visual"/>
                  <geom mesh="link5_1" material="white" class="panda/visual"/>
                  <geom mesh="link5_2" material="white" class="panda/visual"/>
                  <geom mesh="link5_c0" class="panda/collision"/>
                  <geom mesh="link5_c1" class="panda/collision"/>
                  <geom mesh="link5_c2" class="panda/collision"/>
                  <body name="link6" quat="1 1 0 0">
                    <inertial mass="1.666555" pos="6.0149e-2 -1.4117e-2 -1.0517e-2"
                      fullinertia="1.964e-3 4.354e-3 5.433e-3 1.09e-4 -1.158e-3 3.41e-4"/>
                    <joint name="joint6" range="-0.0175 3.7525"/>
                    <site name="joint6"/>
                    <geom mesh="link6_0" material="off_white" class="panda/visual"/>
                    <geom mesh="link6_1" material="white" class="panda/visual"/>
                    <geom mesh="link6_2" material="dark_grey" class="panda/visual"/>
                    <geom mesh="link6_3" material="white" class="panda/visual"/>
                    <geom mesh="link6_4" material="white" class="panda/visual"/>
                    <geom mesh="link6_5" material="white" class="panda/visual"/>
                    <geom mesh="link6_6" material="white" class="panda/visual"/>
                    <geom mesh="link6_7" material="light_blue" class="panda/visual"/>
                    <geom mesh="link6_8" material="light_blue" class="panda/visual"/>
                    <geom mesh="link6_9" material="dark_grey" class="panda/visual"/>
                    <geom mesh="link6_10" material="dark_grey" class="panda/visual"/>
                    <geom mesh="link6_11" material="white" class="panda/visual"/>
                    <geom mesh="link6_12" material="green" class="panda/visual"/>
                    <geom mesh="link6_13" material="white" class="panda/visual"/>
                    <geom mesh="link6_14" material="dark_grey" class="panda/visual"/>
                    <geom mesh="link6_15" material="dark_grey" class="panda/visual"/>
                    <geom mesh="link6_16" material="white" class="panda/visual"/>
                    <geom mesh="link6_c" class="panda/collision"/>
                    <body name="link7" pos="0.088 0 0" quat="1 1 0 0">
                      <inertial mass="7.35522e-01" pos="1.0517e-2 -4.252e-3 6.1597e-2"
                        fullinertia="1.2516e-2 1.0027e-2 4.815e-3 -4.28e-4 -1.196e-3 -7.41e-4"/>
                      <joint name="joint7"/>
                      <site name="joint7"/>
                      <geom mesh="link7_0" material="white" class="panda/visual"/>
                      <geom mesh="link7_1" material="dark_grey" class="panda/visual"/>
                      <geom mesh="link7_2" material="dark_grey" class="panda/visual"/>
                      <geom mesh="link7_3" material="dark_grey" class="panda/visual"/>
                      <geom mesh="link7_4" material="dark_grey" class="panda/visual"/>
                      <geom mesh="link7_5" material="dark_grey" class="panda/visual"/>
                      <geom mesh="link7_6" material="dark_grey" class="panda/visual"/>
                      <geom mesh="link7_7" material="white" class="panda/visual"/>
                      <geom mesh="link7_c" class="panda/collision"/>
                      <body name="attachment" pos="0 0 0.107" quat="0.3826834 0 0 0.9238795">
                        <camera name="handcam_depth" pos="-0.05 0 0" fovy="62" quat="0 1 -1 0"/>
                        <!-- <camera name="handcam_rgb" pos="-0.05 0.015 0" fovy="42.5" quat="0 1 -1 0"/> -->
                        <camera name="handcam_rgb" pos="0.05 0.015 -0.06" fovy="42.5" quat="0 1 -1 0"/>
                        <site name="attachment_site" quat="0 0 0 1"/>
                        <body name="gripper_base" childclass="changingtek" quat="0 0 0 -1">
                          <geom type="mesh" mesh="gripper_base_0" material="white" class="changingtek/visual"/>
                          <geom type="mesh" mesh="gripper_base_1" material="silver" class="changingtek/visual"/>
                          <geom type="mesh" mesh="gripper_base_2" material="black_metal" class="changingtek/visual"/>
                          <geom type="mesh" class="changingtek/collision" mesh="gripper_base_collision_0"/>
                          <geom type="mesh" class="changingtek/collision" mesh="gripper_base_collision_1"/>
                          <geom type="mesh" class="changingtek/collision" mesh="gripper_base_collision_2"/>
                          <site name="pinch" pos="0 0 0.19"/>
                          <body name="eef" pos="0 0 0.19">
                            <site name="grip_site" size="0.01 0.01 0.01" rgba="1 0 0 0.5" type="sphere" class="changingtek/visual"/>
                          </body>
                          <body name="left_1_link" pos="0 -0.030141 0.090147" quat="0.7071054825112363 0.7071080798594735 0.0 0.0">
                            <inertial pos="-1.28088127539536E-18 0.0252734640095115 -0.00214040614650292" quat="1.0 0.0 0.0 0.0"
                              mass="0.0129014357535444"
                              diaginertia="3.35976482443235e-06 1.65185846940368e-07 3.25394125032869e-06"/>
                            <joint name="gripper_joint" type="hinge" range="0 1" axis="1 0 0"/>
                            <geom type="mesh" mesh="link_1" material="black_metal" class="changingtek/visual"/>
                            <geom type="mesh" class="changingtek/collision" mesh="link_1_collision_0"/>
                            <geom type="mesh" class="changingtek/collision" mesh="link_1_collision_1"/>
                            <geom type="mesh" class="changingtek/collision" mesh="link_1_collision_2"/>
                            <body name="left_in_link" pos="0 0.023914 -0.0020253" quat="1.0 0.0 0.0 0.0">
                              <inertial pos="-1.75682286192042E-11 -0.0108820145632286 -0.00405362317350415" quat="1.0 0.0 0.0 0.0"
                                mass="0.0134557296415635"
                                diaginertia="1.43307384392376e-06 3.88838933230828e-07 1.33747540965672e-06"/>
                              <joint name="left_in_Joint" type="hinge" range="0 1" axis="-1 0 0"/>
                              <geom type="mesh" mesh="in_link" material="black_metal" class="changingtek/visual"/>
                              <geom type="mesh" class="changingtek/collision" mesh="in_link_collision_0"/>
                              <geom type="mesh" class="changingtek/collision" mesh="in_link_collision_1"/>
                              <geom type="mesh" class="changingtek/collision" mesh="in_link_collision_2"/>
                            </body>
                            <body name="left_up_link" pos="0 0.054804 -0.0046413" quat="1.0 0.0 0.0 0.0">
                              <inertial pos="8.69802213948566E-11 0.0124078988097444 -0.0072525614743534" quat="1.0 0.0 0.0 0.0"
                                mass="0.014692561982481"
                                diaginertia="2.35283034039115e-06 5.8942945477579e-07 2.07228020361883e-06"/>
                              <joint name="left_up_Joint" type="hinge" range="0 1" axis="-1 0 0"/>
                              <geom type="mesh" mesh="up_link_0" material="silver" class="changingtek/visual"/>
                              <geom type="mesh" mesh="up_link_1" material="black_metal" class="changingtek/visual"/>
                              <geom type="mesh" class="changingtek/collision" mesh="up_link_collision_0"/>
                              <geom type="mesh" class="changingtek/collision" mesh="up_link_collision_1"/>
                              <geom type="mesh" class="changingtek/collision" mesh="up_link_collision_2"/>
                              <body name="left_Pad_link" pos="0 0.04125 -0.02425" quat="1.0 0.0 0.0 0.0">
                                <inertial pos="-3.83777509579761E-08 0.00303135276101582 0.0028336970357949" quat="1.0 0.0 0.0 0.0"
                                  mass="0.0183171479595721"
                                  diaginertia="2.35683098270332e-06 9.08136064346118e-07 3.18448591439082e-06"/>
                                <!-- <geom type="mesh" mesh="pad_link" material="black_rubber" class="changingtek/visual"/>
                                <geom type="mesh" class="changingtek/collision" mesh="pad_link_collision_0"/>
                                <geom type="mesh" class="changingtek/collision" mesh="pad_link_collision_1"/>
                                <geom type="mesh" class="changingtek/collision" mesh="pad_link_collision_2"/> -->
                                <geom type="mesh" mesh="pad_link" material="black_rubber" class="changingtek/visual"/>
                                <geom type="mesh" class="changingtek/collision" mesh="pad_link_collision_0" friction="4.0 0.5 0.5"/>
                                <geom type="mesh" class="changingtek/collision" mesh="pad_link_collision_1" friction="4.0 0.5 0.5"/>
                                <geom type="mesh" class="changingtek/collision" mesh="pad_link_collision_2" friction="4.0 0.5 0.5"/>

                              </body>
                            </body>
                          </body>
                          <body name="left_2_link" pos="0 -0.016 0.107" quat="0.7071054825112363 0.7071080798594735 0.0 0.0">
                            <inertial pos="5.08224485200288E-06 0.0327050710040551 -0.00276963392800038" quat="1.0 0.0 0.0 0.0"
                              mass="0.0188752657753052"
                              diaginertia="3.4145090175335e-06 2.86837057727488e-07 3.39111483394506e-06"/>
                            <joint name="left_2_Joint" type="hinge" range="0 1" axis="1 0 0"/>
                            <geom type="mesh" mesh="link_2_0" material="silver" class="changingtek/visual"/>
                            <geom type="mesh" mesh="link_2_1" material="black_metal" class="changingtek/visual"/>
                            <geom type="mesh" class="changingtek/collision" mesh="link_2_collision_0"/>
                            <geom type="mesh" class="changingtek/collision" mesh="link_2_collision_1"/>
                            <geom type="mesh" class="changingtek/collision" mesh="link_2_collision_2"/>
                          </body>
                          <body name="right_2_link" pos="0 0.016 0.107"
                            quat="-2.5973434669646147e-06 -2.597353007557415e-06 0.7071080798547033 0.707105482506466">
                            <inertial pos="1.94651792710713E-17 0.0327174794493866 -0.00277053098700989" quat="1.0 0.0 0.0 0.0"
                              mass="0.0188856364479881"
                              diaginertia="3.41458781978465e-06 2.86883124998043e-07 3.39114800103702e-06"/>
                            <joint name="right_2_Joint" type="hinge" range="0 1" axis="1 0 0"/>
                            <geom type="mesh" mesh="link_2_0" material="silver" class="changingtek/visual"/>
                            <geom type="mesh" mesh="link_2_1" material="black_metal" class="changingtek/visual"/>
                            <geom type="mesh" class="changingtek/collision" mesh="link_2_collision_0"/>
                            <geom type="mesh" class="changingtek/collision" mesh="link_2_collision_1"/>
                            <geom type="mesh" class="changingtek/collision" mesh="link_2_collision_2"/>
                          </body>
                          <body name="right_1_link" pos="0 0.030141 0.090147"
                            quat="-2.5973434669646147e-06 -2.597353007557415e-06 0.7071080798547033 0.707105482506466">
                            <inertial pos="-5.25233292439781E-19 0.0252734640095115 -0.00214040614650291" quat="1.0 0.0 0.0 0.0"
                              mass="0.0129014357535444"
                              diaginertia="3.35976482443235e-06 1.65185846940368e-07 3.25394125032869e-06"/>
                            <joint name="right_1_Joint" type="hinge" range="0 1" axis="1 0 0"/>
                            <geom type="mesh" mesh="link_1" material="black_metal" class="changingtek/visual"/>
                            <geom type="mesh" class="changingtek/collision" mesh="link_1_collision_0"/>
                            <geom type="mesh" class="changingtek/collision" mesh="link_1_collision_1"/>
                            <geom type="mesh" class="changingtek/collision" mesh="link_1_collision_2"/>
                            <body name="right_in_link" pos="0 0.023914 -0.0020253" quat="1.0 0.0 0.0 0.0">
                              <inertial pos="-1.7568261982498E-11 -0.0108820145632292 -0.00405362317350229" quat="1.0 0.0 0.0 0.0"
                                mass="0.0134557296415635"
                                diaginertia="1.43307384392376e-06 3.88838933230828e-07 1.33747540965672e-06"/>
                              <joint name="right_in_Joint" type="hinge" range="0 1" axis="-1 0 0"/>
                              <geom type="mesh" mesh="in_link" material="black_metal" class="changingtek/visual"/>
                              <geom type="mesh" class="changingtek/collision" mesh="in_link_collision_0"/>
                              <geom type="mesh" class="changingtek/collision" mesh="in_link_collision_1"/>
                              <geom type="mesh" class="changingtek/collision" mesh="in_link_collision_2"/>
                            </body>
                            <body name="right_up_link" pos="0 0.054804 -0.0046413" quat="1.0 0.0 0.0 0.0">
                              <inertial pos="8.69814518862609E-11 0.0124078988097266 -0.00725256147435587" quat="1.0 0.0 0.0 0.0"
                                mass="0.014692561982481"
                                diaginertia="2.35283034039115e-06 5.89429454773258e-07 2.07228020362137e-06"/>
                              <joint name="right_up_Joint" type="hinge" range="0 1" axis="-1 0 0"/>
                              <geom type="mesh" mesh="up_link_0" material="silver" class="changingtek/visual"/>
                              <geom type="mesh" mesh="up_link_1" material="black_metal" class="changingtek/visual"/>
                              <geom type="mesh" class="changingtek/collision" mesh="up_link_collision_0"/>
                              <geom type="mesh" class="changingtek/collision" mesh="up_link_collision_1"/>
                              <geom type="mesh" class="changingtek/collision" mesh="up_link_collision_2"/>
                              <body name="right_Pad_link" pos="0 0.04125 -0.02425" quat="1.0 0.0 0.0 0.0">
                                <inertial pos="-3.83777500494227E-08 0.0030313527610159 0.00283369703564792" quat="1.0 0.0 0.0 0.0"
                                  mass="0.0366342959191441"
                                  diaginertia="4.71366196540664e-06 1.81627212869223e-06 6.36897182878164e-06"/>
                                <!-- <geom type="mesh" mesh="pad_link" material="black_rubber" class="changingtek/visual"/>
                                <geom type="mesh" class="changingtek/collision" mesh="pad_link_collision_0"/>
                                <geom type="mesh" class="changingtek/collision" mesh="pad_link_collision_1"/>
                                <geom type="mesh" class="changingtek/collision" mesh="pad_link_collision_2"/> -->
                                <geom type="mesh" mesh="pad_link" material="black_rubber" class="changingtek/visual"/>
                                <geom type="mesh" class="changingtek/collision" mesh="pad_link_collision_0" friction="4.0 0.5 0.5"/>
                                <geom type="mesh" class="changingtek/collision" mesh="pad_link_collision_1" friction="4.0 0.5 0.5"/>
                                <geom type="mesh" class="changingtek/collision" mesh="pad_link_collision_2" friction="4.0 0.5 0.5"/>

                              </body>
                            </body>
                          </body>
                        </body>
                      </body>
                    </body>
                  </body>
                </body>
              </body>
            </body>
          </body>
        </body>
      </body>
    </worldbody>

    <contact>
      <exclude body1="gripper_base" body2="left_1_link"/>
      <exclude body1="left_1_link" body2="left_in_link"/>
      <exclude body1="left_1_link" body2="left_up_link"/>
      <exclude body1="left_up_link" body2="left_Pad_link"/>
      <exclude body1="gripper_base" body2="left_2_link"/>
      <exclude body1="gripper_base" body2="right_2_link"/>
      <exclude body1="gripper_base" body2="right_1_link"/>
      <exclude body1="right_1_link" body2="right_in_link"/>
      <exclude body1="right_1_link" body2="right_up_link"/>
      <exclude body1="right_up_link" body2="right_Pad_link"/>
    </contact>

    <equality>
      <joint joint1="gripper_joint" joint2="left_in_Joint" polycoef="0.0 10.0 0 0 0" solimp="0.95 0.99 0.001"
        solref="0.005 1"/>
      <joint joint1="gripper_joint" joint2="left_up_Joint" polycoef="0.0 1.0 0 0 0" solimp="0.95 0.99 0.001"
        solref="0.005 1"/>
      <joint joint1="gripper_joint" joint2="left_2_Joint" polycoef="0.0 1.0 0 0 0" solimp="0.95 0.99 0.001"
        solref="0.005 1"/>
      <joint joint1="gripper_joint" joint2="right_2_Joint" polycoef="0.0 1.0 0 0 0" solimp="0.95 0.99 0.001"
        solref="0.005 1"/>
      <joint joint1="gripper_joint" joint2="right_1_Joint" polycoef="0.0 1.0 0 0 0" solimp="0.95 0.99 0.001"
        solref="0.005 1"/>
      <joint joint1="gripper_joint" joint2="right_in_Joint" polycoef="0.0 10.0 0 0 0" solimp="0.95 0.99 0.001"
        solref="0.005 1"/>
      <joint joint1="gripper_joint" joint2="right_up_Joint" polycoef="0.0 1.0 0 0 0" solimp="0.95 0.99 0.001"
        solref="0.005 1"/>
    </equality>

    <actuator>
      <motor class="panda" name="actuator1" joint="joint1" ctrlrange="-87 87"/>
      <motor class="panda" name="actuator2" joint="joint2" ctrlrange="-87 87"/>
      <motor class="panda" name="actuator3" joint="joint3" ctrlrange="-87 87"/>
      <motor class="panda" name="actuator4" joint="joint4" ctrlrange="-87 87"/>
      <motor class="panda" name="actuator5" joint="joint5" ctrlrange="-12 12"/>
      <motor class="panda" name="actuator6" joint="joint6" ctrlrange="-12 12"/>
      <motor class="panda" name="actuator7" joint="joint7" ctrlrange="-12 12"/>
      <position name="gripper_actuator" ctrllimited="true" kp="20" kv="0.01" ctrlrange="0 1.0" joint="gripper_joint"/>
    </actuator>

    <sensor>
      <jointpos name="panda/joint1_pos" joint="joint1"/>
      <jointpos name="panda/joint2_pos" joint="joint2"/>
      <jointpos name="panda/joint3_pos" joint="joint3"/>
      <jointpos name="panda/joint4_pos" joint="joint4"/>
      <jointpos name="panda/joint5_pos" joint="joint5"/>
      <jointpos name="panda/joint6_pos" joint="joint6"/>
      <jointpos name="panda/joint7_pos" joint="joint7"/>

      <jointvel name="panda/joint1_vel" joint="joint1"/>
      <jointvel name="panda/joint2_vel" joint="joint2"/>
      <jointvel name="panda/joint3_vel" joint="joint3"/>
      <jointvel name="panda/joint4_vel" joint="joint4"/>
      <jointvel name="panda/joint5_vel" joint="joint5"/>
      <jointvel name="panda/joint6_vel" joint="joint6"/>
      <jointvel name="panda/joint7_vel" joint="joint7"/>

      <torque name="panda/joint1_torque" site="joint1"/>
      <torque name="panda/joint2_torque" site="joint2"/>
      <torque name="panda/joint3_torque" site="joint3"/>
      <torque name="panda/joint4_torque" site="joint4"/>
      <torque name="panda/joint5_torque" site="joint5"/>
      <torque name="panda/joint6_torque" site="joint6"/>
      <torque name="panda/joint7_torque" site="joint7"/>

      <force name="panda/wrist_force" site="attachment_site"/>

      <framepos name="changingtek/pinch_pos" objtype="site" objname="pinch"/>
      <framequat name="changingtek/pinch_quat" objtype="site" objname="pinch"/>
      <framelinvel name="changingtek/pinch_vel" objtype="site" objname="pinch"/>
      <frameangvel name="changingtek/pinch_angvel" objtype="site" objname="pinch"/>
    </sensor>
  </mujoco>
